Workbook

Sheet Summary
A1: source | B1: "solutions_v_s57.{ρ}.4s",
B2: "solutions_v58.{ρ}.4s"
B3: "solutions_v_s57.{ρ}.7.5s"
C22: Operational cost ($) | G22: Expected energy not served cost ($) | K22: Expected energy not server (MWh)
B23: rho (correlationf actor) | C23: conservative | D23: envelope | E23: e-reserve | F23: stochastic | G23: conservative | H23: envelope | I23: e-reserve | J23: stochastic | K23: conservative | L23: envelope | M23: e-reserve | N23: stochastic
B24: 0 | C24: =GETPIVOTDATA("Sum of EOPEX",EOPEX!$N$4,"model_type",C$23,"rho",$B24) -> 808058.21 | D24: =GETPIVOTDATA("Sum of EOPEX",EOPEX!$N$4,"model_type",D$23,"rho",$B24) -> 800627.13 | E24: =GETPIVOTDATA("Sum of EOPEX",EOPEX!$N$4,"model_type",E$23,"rho",$B24) -> 800627.08 | F24: =GETPIVOTDATA("Sum of EOPEX",EOPEX!$N$4,"model_type",F$23,"rho",$B24) -> 796469.72 | G24: =GETPIVOTDATA("Sum of EENS_cost",EOPEX!$N$4,"model_type",G$23,"rho",$B24) -> 0 | H24: =GETPIVOTDATA("Sum of EENS_cost",EOPEX!$N$4,"model_type",H$23,"rho",$B24) -> 0 | I24: =GETPIVOTDATA("Sum of EENS_cost",EOPEX!$N$4,"model_type",I$23,"rho",$B24) -> 0 | J24: =GETPIVOTDATA("Sum of EENS_cost",EOPEX!$N$4,"model_type",J$23,"rho",$B24) -> 0 | K24: =GETPIVOTDATA("EENS",EENS!$A$3,"model_type",Summary!K$23,"rho",Summary!$B24) -> 0 | L24: =GETPIVOTDATA("EENS",EENS!$A$3,"model_type",Summary!L$23,"rho",Summary!$B24) -> 0 | M24: =GETPIVOTDATA("EENS",EENS!$A$3,"model_type",Summary!M$23,"rho",Summary!$B24) -> 0 | N24: =GETPIVOTDATA("EENS",EENS!$A$3,"model_type",Summary!N$23,"rho",Summary!$B24) -> 0
B25: 0.1 | C25: =GETPIVOTDATA("Sum of EOPEX",EOPEX!$N$4,"model_type",C$23,"rho",$B25) -> 807863.59 | D25: =GETPIVOTDATA("Sum of EOPEX",EOPEX!$N$4,"model_type",D$23,"rho",$B25) -> 800160.25 | E25: =GETPIVOTDATA("Sum of EOPEX",EOPEX!$N$4,"model_type",E$23,"rho",$B25) -> 800079.35 | F25: =GETPIVOTDATA("Sum of EOPEX",EOPEX!$N$4,"model_type",F$23,"rho",$B25) -> 795440.88 | G25: =GETPIVOTDATA("Sum of EENS_cost",EOPEX!$N$4,"model_type",G$23,"rho",$B25) -> 0 | H25: =GETPIVOTDATA("Sum of EENS_cost",EOPEX!$N$4,"model_type",H$23,"rho",$B25) -> 0 | I25: =GETPIVOTDATA("Sum of EENS_cost",EOPEX!$N$4,"model_type",I$23,"rho",$B25) -> 0 | J25: =GETPIVOTDATA("Sum of EENS_cost",EOPEX!$N$4,"model_type",J$23,"rho",$B25) -> 0 | K25: =GETPIVOTDATA("EENS",EENS!$A$3,"model_type",Summary!K$23,"rho",Summary!$B25) -> 0 | L25: =GETPIVOTDATA("EENS",EENS!$A$3,"model_type",Summary!L$23,"rho",Summary!$B25) -> 0 | M25: =GETPIVOTDATA("EENS",EENS!$A$3,"model_type",Summary!M$23,"rho",Summary!$B25) -> 0 | N25: =GETPIVOTDATA("EENS",EENS!$A$3,"model_type",Summary!N$23,"rho",Summary!$B25) -> 0
B26: 0.2 | C26: =GETPIVOTDATA("Sum of EOPEX",EOPEX!$N$4,"model_type",C$23,"rho",$B26) -> 811588.96 | D26: =GETPIVOTDATA("Sum of EOPEX",EOPEX!$N$4,"model_type",D$23,"rho",$B26) -> 800452.98 | E26: =GETPIVOTDATA("Sum of EOPEX",EOPEX!$N$4,"model_type",E$23,"rho",$B26) -> 800452.98 | F26: =GETPIVOTDATA("Sum of EOPEX",EOPEX!$N$4,"model_type",F$23,"rho",$B26) -> 796642.79 | G26: =GETPIVOTDATA("Sum of EENS_cost",EOPEX!$N$4,"model_type",G$23,"rho",$B26) -> 0 | H26: =GETPIVOTDATA("Sum of EENS_cost",EOPEX!$N$4,"model_type",H$23,"rho",$B26) -> 6374.5724 | I26: =GETPIVOTDATA("Sum of EENS_cost",EOPEX!$N$4,"model_type",I$23,"rho",$B26) -> 0 | J26: =GETPIVOTDATA("Sum of EENS_cost",EOPEX!$N$4,"model_type",J$23,"rho",$B26) -> 0 | K26: =GETPIVOTDATA("EENS",EENS!$A$3,"model_type",Summary!K$23,"rho",Summary!$B26) -> 0 | L26: =GETPIVOTDATA("EENS",EENS!$A$3,"model_type",Summary!L$23,"rho",Summary!$B26) -> 0.63745724 | M26: =GETPIVOTDATA("EENS",EENS!$A$3,"model_type",Summary!M$23,"rho",Summary!$B26) -> 0 | N26: =GETPIVOTDATA("EENS",EENS!$A$3,"model_type",Summary!N$23,"rho",Summary!$B26) -> 0
B27: 0.3 | C27: =GETPIVOTDATA("Sum of EOPEX",EOPEX!$N$4,"model_type",C$23,"rho",$B27) -> 808877.04 | D27: =GETPIVOTDATA("Sum of EOPEX",EOPEX!$N$4,"model_type",D$23,"rho",$B27) -> 800411.44 | E27: =GETPIVOTDATA("Sum of EOPEX",EOPEX!$N$4,"model_type",E$23,"rho",$B27) -> 800411.44 | F27: =GETPIVOTDATA("Sum of EOPEX",EOPEX!$N$4,"model_type",F$23,"rho",$B27) -> 796530.57 | G27: =GETPIVOTDATA("Sum of EENS_cost",EOPEX!$N$4,"model_type",G$23,"rho",$B27) -> 0 | H27: =GETPIVOTDATA("Sum of EENS_cost",EOPEX!$N$4,"model_type",H$23,"rho",$B27) -> 20217.44 | I27: =GETPIVOTDATA("Sum of EENS_cost",EOPEX!$N$4,"model_type",I$23,"rho",$B27) -> 0 | J27: =GETPIVOTDATA("Sum of EENS_cost",EOPEX!$N$4,"model_type",J$23,"rho",$B27) -> 0 | K27: =GETPIVOTDATA("EENS",EENS!$A$3,"model_type",Summary!K$23,"rho",Summary!$B27) -> 0 | L27: =GETPIVOTDATA("EENS",EENS!$A$3,"model_type",Summary!L$23,"rho",Summary!$B27) -> 2.021744 | M27: =GETPIVOTDATA("EENS",EENS!$A$3,"model_type",Summary!M$23,"rho",Summary!$B27) -> 0 | N27: =GETPIVOTDATA("EENS",EENS!$A$3,"model_type",Summary!N$23,"rho",Summary!$B27) -> 0
B28: 0.4 | C28: =GETPIVOTDATA("Sum of EOPEX",EOPEX!$N$4,"model_type",C$23,"rho",$B28) -> 807195.26 | D28: =GETPIVOTDATA("Sum of EOPEX",EOPEX!$N$4,"model_type",D$23,"rho",$B28) -> 800162.66 | E28: =GETPIVOTDATA("Sum of EOPEX",EOPEX!$N$4,"model_type",E$23,"rho",$B28) -> 800162.66 | F28: =GETPIVOTDATA("Sum of EOPEX",EOPEX!$N$4,"model_type",F$23,"rho",$B28) -> 795701.56 | G28: =GETPIVOTDATA("Sum of EENS_cost",EOPEX!$N$4,"model_type",G$23,"rho",$B28) -> 0 | H28: =GETPIVOTDATA("Sum of EENS_cost",EOPEX!$N$4,"model_type",H$23,"rho",$B28) -> 0 | I28: =GETPIVOTDATA("Sum of EENS_cost",EOPEX!$N$4,"model_type",I$23,"rho",$B28) -> 0 | J28: =GETPIVOTDATA("Sum of EENS_cost",EOPEX!$N$4,"model_type",J$23,"rho",$B28) -> 0 | K28: =GETPIVOTDATA("EENS",EENS!$A$3,"model_type",Summary!K$23,"rho",Summary!$B28) -> 0 | L28: =GETPIVOTDATA("EENS",EENS!$A$3,"model_type",Summary!L$23,"rho",Summary!$B28) -> 0 | M28: =GETPIVOTDATA("EENS",EENS!$A$3,"model_type",Summary!M$23,"rho",Summary!$B28) -> 0 | N28: =GETPIVOTDATA("EENS",EENS!$A$3,"model_type",Summary!N$23,"rho",Summary!$B28) -> 0
B29: 0.5 | C29: =GETPIVOTDATA("Sum of EOPEX",EOPEX!$N$4,"model_type",C$23,"rho",$B29) -> 814114 | D29: =GETPIVOTDATA("Sum of EOPEX",EOPEX!$N$4,"model_type",D$23,"rho",$B29) -> 800062.59 | E29: =GETPIVOTDATA("Sum of EOPEX",EOPEX!$N$4,"model_type",E$23,"rho",$B29) -> 800062.59 | F29: =GETPIVOTDATA("Sum of EOPEX",EOPEX!$N$4,"model_type",F$23,"rho",$B29) -> 795008.52 | G29: =GETPIVOTDATA("Sum of EENS_cost",EOPEX!$N$4,"model_type",G$23,"rho",$B29) -> 0 | H29: =GETPIVOTDATA("Sum of EENS_cost",EOPEX!$N$4,"model_type",H$23,"rho",$B29) -> 0 | I29: =GETPIVOTDATA("Sum of EENS_cost",EOPEX!$N$4,"model_type",I$23,"rho",$B29) -> 0 | J29: =GETPIVOTDATA("Sum of EENS_cost",EOPEX!$N$4,"model_type",J$23,"rho",$B29) -> 0 | K29: =GETPIVOTDATA("EENS",EENS!$A$3,"model_type",Summary!K$23,"rho",Summary!$B29) -> 0 | L29: =GETPIVOTDATA("EENS",EENS!$A$3,"model_type",Summary!L$23,"rho",Summary!$B29) -> 0 | M29: =GETPIVOTDATA("EENS",EENS!$A$3,"model_type",Summary!M$23,"rho",Summary!$B29) -> 0 | N29: =GETPIVOTDATA("EENS",EENS!$A$3,"model_type",Summary!N$23,"rho",Summary!$B29) -> 0
B30: 0.6 | C30: =GETPIVOTDATA("Sum of EOPEX",EOPEX!$N$4,"model_type",C$23,"rho",$B30) -> 810987.91 | D30: =GETPIVOTDATA("Sum of EOPEX",EOPEX!$N$4,"model_type",D$23,"rho",$B30) -> 800598.89 | E30: =GETPIVOTDATA("Sum of EOPEX",EOPEX!$N$4,"model_type",E$23,"rho",$B30) -> 802691.46 | F30: =GETPIVOTDATA("Sum of EOPEX",EOPEX!$N$4,"model_type",F$23,"rho",$B30) -> 796231.63 | G30: =GETPIVOTDATA("Sum of EENS_cost",EOPEX!$N$4,"model_type",G$23,"rho",$B30) -> 0 | H30: =GETPIVOTDATA("Sum of EENS_cost",EOPEX!$N$4,"model_type",H$23,"rho",$B30) -> 0 | I30: =GETPIVOTDATA("Sum of EENS_cost",EOPEX!$N$4,"model_type",I$23,"rho",$B30) -> 0 | J30: =GETPIVOTDATA("Sum of EENS_cost",EOPEX!$N$4,"model_type",J$23,"rho",$B30) -> 0 | K30: =GETPIVOTDATA("EENS",EENS!$A$3,"model_type",Summary!K$23,"rho",Summary!$B30) -> 0 | L30: =GETPIVOTDATA("EENS",EENS!$A$3,"model_type",Summary!L$23,"rho",Summary!$B30) -> 0 | M30: =GETPIVOTDATA("EENS",EENS!$A$3,"model_type",Summary!M$23,"rho",Summary!$B30) -> 0 | N30: =GETPIVOTDATA("EENS",EENS!$A$3,"model_type",Summary!N$23,"rho",Summary!$B30) -> 0
B31: 0.7 | C31: =GETPIVOTDATA("Sum of EOPEX",EOPEX!$N$4,"model_type",C$23,"rho",$B31) -> 807595.44 | D31: =GETPIVOTDATA("Sum of EOPEX",EOPEX!$N$4,"model_type",D$23,"rho",$B31) -> 802775.11 | E31: =GETPIVOTDATA("Sum of EOPEX",EOPEX!$N$4,"model_type",E$23,"rho",$B31) -> 803581.04 | F31: =GETPIVOTDATA("Sum of EOPEX",EOPEX!$N$4,"model_type",F$23,"rho",$B31) -> 795787.74 | G31: =GETPIVOTDATA("Sum of EENS_cost",EOPEX!$N$4,"model_type",G$23,"rho",$B31) -> 0 | H31: =GETPIVOTDATA("Sum of EENS_cost",EOPEX!$N$4,"model_type",H$23,"rho",$B31) -> 0 | I31: =GETPIVOTDATA("Sum of EENS_cost",EOPEX!$N$4,"model_type",I$23,"rho",$B31) -> 0 | J31: =GETPIVOTDATA("Sum of EENS_cost",EOPEX!$N$4,"model_type",J$23,"rho",$B31) -> 0 | K31: =GETPIVOTDATA("EENS",EENS!$A$3,"model_type",Summary!K$23,"rho",Summary!$B31) -> 0 | L31: =GETPIVOTDATA("EENS",EENS!$A$3,"model_type",Summary!L$23,"rho",Summary!$B31) -> 0 | M31: =GETPIVOTDATA("EENS",EENS!$A$3,"model_type",Summary!M$23,"rho",Summary!$B31) -> 0 | N31: =GETPIVOTDATA("EENS",EENS!$A$3,"model_type",Summary!N$23,"rho",Summary!$B31) -> 0
B32: 0.8 | C32: =GETPIVOTDATA("Sum of EOPEX",EOPEX!$N$4,"model_type",C$23,"rho",$B32) -> 807664.97 | D32: =GETPIVOTDATA("Sum of EOPEX",EOPEX!$N$4,"model_type",D$23,"rho",$B32) -> 804182.05 | E32: =GETPIVOTDATA("Sum of EOPEX",EOPEX!$N$4,"model_type",E$23,"rho",$B32) -> 805872.16 | F32: =GETPIVOTDATA("Sum of EOPEX",EOPEX!$N$4,"model_type",F$23,"rho",$B32) -> 796267.35 | G32: =GETPIVOTDATA("Sum of EENS_cost",EOPEX!$N$4,"model_type",G$23,"rho",$B32) -> 0 | H32: =GETPIVOTDATA("Sum of EENS_cost",EOPEX!$N$4,"model_type",H$23,"rho",$B32) -> 0 | I32: =GETPIVOTDATA("Sum of EENS_cost",EOPEX!$N$4,"model_type",I$23,"rho",$B32) -> 0 | J32: =GETPIVOTDATA("Sum of EENS_cost",EOPEX!$N$4,"model_type",J$23,"rho",$B32) -> 0 | K32: =GETPIVOTDATA("EENS",EENS!$A$3,"model_type",Summary!K$23,"rho",Summary!$B32) -> 0 | L32: =GETPIVOTDATA("EENS",EENS!$A$3,"model_type",Summary!L$23,"rho",Summary!$B32) -> 0 | M32: =GETPIVOTDATA("EENS",EENS!$A$3,"model_type",Summary!M$23,"rho",Summary!$B32) -> 0 | N32: =GETPIVOTDATA("EENS",EENS!$A$3,"model_type",Summary!N$23,"rho",Summary!$B32) -> 0
B33: 0.9 | C33: =GETPIVOTDATA("Sum of EOPEX",EOPEX!$N$4,"model_type",C$23,"rho",$B33) -> 813620.18 | D33: =GETPIVOTDATA("Sum of EOPEX",EOPEX!$N$4,"model_type",D$23,"rho",$B33) -> 805560.34 | E33: =GETPIVOTDATA("Sum of EOPEX",EOPEX!$N$4,"model_type",E$23,"rho",$B33) -> 805930.4 | F33: =GETPIVOTDATA("Sum of EOPEX",EOPEX!$N$4,"model_type",F$23,"rho",$B33) -> 798514 | G33: =GETPIVOTDATA("Sum of EENS_cost",EOPEX!$N$4,"model_type",G$23,"rho",$B33) -> 0 | H33: =GETPIVOTDATA("Sum of EENS_cost",EOPEX!$N$4,"model_type",H$23,"rho",$B33) -> 0 | I33: =GETPIVOTDATA("Sum of EENS_cost",EOPEX!$N$4,"model_type",I$23,"rho",$B33) -> 0 | J33: =GETPIVOTDATA("Sum of EENS_cost",EOPEX!$N$4,"model_type",J$23,"rho",$B33) -> 0 | K33: =GETPIVOTDATA("EENS",EENS!$A$3,"model_type",Summary!K$23,"rho",Summary!$B33) -> 0 | L33: =GETPIVOTDATA("EENS",EENS!$A$3,"model_type",Summary!L$23,"rho",Summary!$B33) -> 0 | M33: =GETPIVOTDATA("EENS",EENS!$A$3,"model_type",Summary!M$23,"rho",Summary!$B33) -> 0 | N33: =GETPIVOTDATA("EENS",EENS!$A$3,"model_type",Summary!N$23,"rho",Summary!$B33) -> 0
B34: 0.99 | C34: =GETPIVOTDATA("Sum of EOPEX",EOPEX!$N$4,"model_type",C$23,"rho",$B34) -> 805431.84 | D34: =GETPIVOTDATA("Sum of EOPEX",EOPEX!$N$4,"model_type",D$23,"rho",$B34) -> 805351.04 | E34: =GETPIVOTDATA("Sum of EOPEX",EOPEX!$N$4,"model_type",E$23,"rho",$B34) -> 805380.27 | F34: =GETPIVOTDATA("Sum of EOPEX",EOPEX!$N$4,"model_type",F$23,"rho",$B34) -> 800265.81 | G34: =GETPIVOTDATA("Sum of EENS_cost",EOPEX!$N$4,"model_type",G$23,"rho",$B34) -> 0 | H34: =GETPIVOTDATA("Sum of EENS_cost",EOPEX!$N$4,"model_type",H$23,"rho",$B34) -> 6240.7091 | I34: =GETPIVOTDATA("Sum of EENS_cost",EOPEX!$N$4,"model_type",I$23,"rho",$B34) -> 0 | J34: =GETPIVOTDATA("Sum of EENS_cost",EOPEX!$N$4,"model_type",J$23,"rho",$B34) -> 0 | K34: =GETPIVOTDATA("EENS",EENS!$A$3,"model_type",Summary!K$23,"rho",Summary!$B34) -> 0 | L34: =GETPIVOTDATA("EENS",EENS!$A$3,"model_type",Summary!L$23,"rho",Summary!$B34) -> 0.62407091 | M34: =GETPIVOTDATA("EENS",EENS!$A$3,"model_type",Summary!M$23,"rho",Summary!$B34) -> 0 | N34: =GETPIVOTDATA("EENS",EENS!$A$3,"model_type",Summary!N$23,"rho",Summary!$B34) -> 0
C38: Operational cost ($) | G38: Expected energy not served cost ($) | H38: Expected energy not server (MWh)
B39: rho (correlationf actor) | C39: conservative | D39: envelope | E39: e-reserve | F39: stochastic | G39: envelope | H39: envelope
B40: 0 | C40: =GETPIVOTDATA("Sum of EOPEX",EOPEX!$N$4,"model_type",C$23,"rho",$B40) -> 808058.21 | D40: =GETPIVOTDATA("Sum of EOPEX",EOPEX!$N$4,"model_type",D$23,"rho",$B40) -> 800627.13 | E40: =GETPIVOTDATA("Sum of EOPEX",EOPEX!$N$4,"model_type",E$23,"rho",$B40) -> 800627.08 | F40: =GETPIVOTDATA("Sum of EOPEX",EOPEX!$N$4,"model_type",F$23,"rho",$B40) -> 796469.72 | G40: =GETPIVOTDATA("Sum of EENS_cost",EOPEX!$N$4,"model_type",H$23,"rho",$B40) -> 0 | H40: =GETPIVOTDATA("EENS",EENS!$A$3,"model_type",Summary!L$23,"rho",Summary!$B40) -> 0
B41: 0.1 | C41: =GETPIVOTDATA("Sum of EOPEX",EOPEX!$N$4,"model_type",C$23,"rho",$B41) -> 807863.59 | D41: =GETPIVOTDATA("Sum of EOPEX",EOPEX!$N$4,"model_type",D$23,"rho",$B41) -> 800160.25 | E41: =GETPIVOTDATA("Sum of EOPEX",EOPEX!$N$4,"model_type",E$23,"rho",$B41) -> 800079.35 | F41: =GETPIVOTDATA("Sum of EOPEX",EOPEX!$N$4,"model_type",F$23,"rho",$B41) -> 795440.88 | G41: =GETPIVOTDATA("Sum of EENS_cost",EOPEX!$N$4,"model_type",H$23,"rho",$B41) -> 0 | H41: =GETPIVOTDATA("EENS",EENS!$A$3,"model_type",Summary!L$23,"rho",Summary!$B41) -> 0
B42: 0.2 | C42: =GETPIVOTDATA("Sum of EOPEX",EOPEX!$N$4,"model_type",C$23,"rho",$B42) -> 811588.96 | D42: =GETPIVOTDATA("Sum of EOPEX",EOPEX!$N$4,"model_type",D$23,"rho",$B42) -> 800452.98 | E42: =GETPIVOTDATA("Sum of EOPEX",EOPEX!$N$4,"model_type",E$23,"rho",$B42) -> 800452.98 | F42: =GETPIVOTDATA("Sum of EOPEX",EOPEX!$N$4,"model_type",F$23,"rho",$B42) -> 796642.79 | G42: =GETPIVOTDATA("Sum of EENS_cost",EOPEX!$N$4,"model_type",H$23,"rho",$B42) -> 6374.5724 | H42: =GETPIVOTDATA("EENS",EENS!$A$3,"model_type",Summary!L$23,"rho",Summary!$B42) -> 0.63745724
B43: 0.3 | C43: =GETPIVOTDATA("Sum of EOPEX",EOPEX!$N$4,"model_type",C$23,"rho",$B43) -> 808877.04 | D43: =GETPIVOTDATA("Sum of EOPEX",EOPEX!$N$4,"model_type",D$23,"rho",$B43) -> 800411.44 | E43: =GETPIVOTDATA("Sum of EOPEX",EOPEX!$N$4,"model_type",E$23,"rho",$B43) -> 800411.44 | F43: =GETPIVOTDATA("Sum of EOPEX",EOPEX!$N$4,"model_type",F$23,"rho",$B43) -> 796530.57 | G43: =GETPIVOTDATA("Sum of EENS_cost",EOPEX!$N$4,"model_type",H$23,"rho",$B43) -> 20217.44 | H43: =GETPIVOTDATA("EENS",EENS!$A$3,"model_type",Summary!L$23,"rho",Summary!$B43) -> 2.021744
B44: 0.4 | C44: =GETPIVOTDATA("Sum of EOPEX",EOPEX!$N$4,"model_type",C$23,"rho",$B44) -> 807195.26 | D44: =GETPIVOTDATA("Sum of EOPEX",EOPEX!$N$4,"model_type",D$23,"rho",$B44) -> 800162.66 | E44: =GETPIVOTDATA("Sum of EOPEX",EOPEX!$N$4,"model_type",E$23,"rho",$B44) -> 800162.66 | F44: =GETPIVOTDATA("Sum of EOPEX",EOPEX!$N$4,"model_type",F$23,"rho",$B44) -> 795701.56 | G44: =GETPIVOTDATA("Sum of EENS_cost",EOPEX!$N$4,"model_type",H$23,"rho",$B44) -> 0 | H44: =GETPIVOTDATA("EENS",EENS!$A$3,"model_type",Summary!L$23,"rho",Summary!$B44) -> 0
B45: 0.5 | C45: =GETPIVOTDATA("Sum of EOPEX",EOPEX!$N$4,"model_type",C$23,"rho",$B45) -> 814114 | D45: =GETPIVOTDATA("Sum of EOPEX",EOPEX!$N$4,"model_type",D$23,"rho",$B45) -> 800062.59 | E45: =GETPIVOTDATA("Sum of EOPEX",EOPEX!$N$4,"model_type",E$23,"rho",$B45) -> 800062.59 | F45: =GETPIVOTDATA("Sum of EOPEX",EOPEX!$N$4,"model_type",F$23,"rho",$B45) -> 795008.52 | G45: =GETPIVOTDATA("Sum of EENS_cost",EOPEX!$N$4,"model_type",H$23,"rho",$B45) -> 0 | H45: =GETPIVOTDATA("EENS",EENS!$A$3,"model_type",Summary!L$23,"rho",Summary!$B45) -> 0
B46: 0.6 | C46: =GETPIVOTDATA("Sum of EOPEX",EOPEX!$N$4,"model_type",C$23,"rho",$B46) -> 810987.91 | D46: =GETPIVOTDATA("Sum of EOPEX",EOPEX!$N$4,"model_type",D$23,"rho",$B46) -> 800598.89 | E46: =GETPIVOTDATA("Sum of EOPEX",EOPEX!$N$4,"model_type",E$23,"rho",$B46) -> 802691.46 | F46: =GETPIVOTDATA("Sum of EOPEX",EOPEX!$N$4,"model_type",F$23,"rho",$B46) -> 796231.63 | G46: =GETPIVOTDATA("Sum of EENS_cost",EOPEX!$N$4,"model_type",H$23,"rho",$B46) -> 0 | H46: =GETPIVOTDATA("EENS",EENS!$A$3,"model_type",Summary!L$23,"rho",Summary!$B46) -> 0
B47: 0.7 | C47: =GETPIVOTDATA("Sum of EOPEX",EOPEX!$N$4,"model_type",C$23,"rho",$B47) -> 807595.44 | D47: =GETPIVOTDATA("Sum of EOPEX",EOPEX!$N$4,"model_type",D$23,"rho",$B47) -> 802775.11 | E47: =GETPIVOTDATA("Sum of EOPEX",EOPEX!$N$4,"model_type",E$23,"rho",$B47) -> 803581.04 | F47: =GETPIVOTDATA("Sum of EOPEX",EOPEX!$N$4,"model_type",F$23,"rho",$B47) -> 795787.74 | G47: =GETPIVOTDATA("Sum of EENS_cost",EOPEX!$N$4,"model_type",H$23,"rho",$B47) -> 0 | H47: =GETPIVOTDATA("EENS",EENS!$A$3,"model_type",Summary!L$23,"rho",Summary!$B47) -> 0
B48: 0.8 | C48: =GETPIVOTDATA("Sum of EOPEX",EOPEX!$N$4,"model_type",C$23,"rho",$B48) -> 807664.97 | D48: =GETPIVOTDATA("Sum of EOPEX",EOPEX!$N$4,"model_type",D$23,"rho",$B48) -> 804182.05 | E48: =GETPIVOTDATA("Sum of EOPEX",EOPEX!$N$4,"model_type",E$23,"rho",$B48) -> 805872.16 | F48: =GETPIVOTDATA("Sum of EOPEX",EOPEX!$N$4,"model_type",F$23,"rho",$B48) -> 796267.35 | G48: =GETPIVOTDATA("Sum of EENS_cost",EOPEX!$N$4,"model_type",H$23,"rho",$B48) -> 0 | H48: =GETPIVOTDATA("EENS",EENS!$A$3,"model_type",Summary!L$23,"rho",Summary!$B48) -> 0
B49: 0.9 | C49: =GETPIVOTDATA("Sum of EOPEX",EOPEX!$N$4,"model_type",C$23,"rho",$B49) -> 813620.18 | D49: =GETPIVOTDATA("Sum of EOPEX",EOPEX!$N$4,"model_type",D$23,"rho",$B49) -> 805560.34 | E49: =GETPIVOTDATA("Sum of EOPEX",EOPEX!$N$4,"model_type",E$23,"rho",$B49) -> 805930.4 | F49: =GETPIVOTDATA("Sum of EOPEX",EOPEX!$N$4,"model_type",F$23,"rho",$B49) -> 798514 | G49: =GETPIVOTDATA("Sum of EENS_cost",EOPEX!$N$4,"model_type",H$23,"rho",$B49) -> 0 | H49: =GETPIVOTDATA("EENS",EENS!$A$3,"model_type",Summary!L$23,"rho",Summary!$B49) -> 0
B50: 0.99 | C50: =GETPIVOTDATA("Sum of EOPEX",EOPEX!$N$4,"model_type",C$23,"rho",$B50) -> 805431.84 | D50: =GETPIVOTDATA("Sum of EOPEX",EOPEX!$N$4,"model_type",D$23,"rho",$B50) -> 805351.04 | E50: =GETPIVOTDATA("Sum of EOPEX",EOPEX!$N$4,"model_type",E$23,"rho",$B50) -> 805380.27 | F50: =GETPIVOTDATA("Sum of EOPEX",EOPEX!$N$4,"model_type",F$23,"rho",$B50) -> 800265.81 | G50: =GETPIVOTDATA("Sum of EENS_cost",EOPEX!$N$4,"model_type",H$23,"rho",$B50) -> 6240.7091 | H50: =GETPIVOTDATA("EENS",EENS!$A$3,"model_type",Summary!L$23,"rho",Summary!$B50) -> 0.62407091
C52: Operational cost ($) | G52: Expected energy not served cost ($) | H52: Expected energy not server (MWh)
B53: rho (correlationf actor) | C53: conservative | D53: envelope | E53: e-reserve | F53: stochastic | G53: envelope | H53: envelope
B54: 0 | C54: 808058.21 | D54: 800627.13 | E54: 800627.08 | F54: 796469.72 | G54: 0 | H54: 0
B55: 0.1 | C55: 807863.59 | D55: 800160.25 | E55: 800079.35 | F55: 795440.88 | G55: 0 | H55: 0
B56: 0.2 | C56: 811588.96 | D56: 800452.98 | E56: 800452.98 | F56: 796642.79 | G56: 6374.5724 | H56: 0.63745724
B57: 0.3 | C57: 808877.04 | D57: 800411.44 | E57: 800411.44 | F57: 796530.57 | G57: 20217.44 | H57: 2.021744
B58: 0.4 | C58: 807195.26 | D58: 800162.66 | E58: 800162.66 | F58: 795701.56 | G58: 0 | H58: 0
B59: 0.5 | C59: 814114 | D59: 800062.59 | E59: 800062.59 | F59: 795008.52 | G59: 0 | H59: 0
B60: 0.6 | C60: 810987.91 | D60: 800598.89 | E60: 802691.46 | F60: 796231.63 | G60: 0 | H60: 0
B61: 0.7 | C61: 807595.44 | D61: 802775.11 | E61: 803581.04 | F61: 795787.74 | G61: 0 | H61: 0
B62: 0.8 | C62: 807664.97 | D62: 804182.05 | E62: 805872.16 | F62: 796267.35 | G62: 0 | H62: 0
...

Sheet LGEN
A3: Sum of ELGEN | B3: Column Labels
A4: Row Labels | B4: envelope | C4: e-reserve | D4: conservative | E4: stochastic
A5: 0 | B5: 0 | C5: 0 | D5: 0 | E5: 0
A6: 0.1 | B6: 0 | C6: 0 | D6: 0 | E6: 0
A7: 0.2 | B7: 0 | C7: -2.8990144e-14 | D7: 0 | E7: 0
A8: 0.3 | B8: 0 | C8: 0 | D8: 0 | E8: 0
A9: 0.4 | B9: 0 | C9: 0 | D9: 0 | E9: 0
A10: 0.5 | B10: 0 | C10: 0 | D10: 0 | E10: 0
A11: 0.6 | B11: 0 | C11: 0 | D11: 0 | E11: 0
A12: 0.7 | B12: 0 | C12: 0 | D12: 0 | E12: 0
A13: 0.8 | B13: 0 | C13: 0 | D13: 0 | E13: 0.6461977
A14: 0.9 | B14: 0 | C14: 0 | D14: 0 | E14: 0.324704
A15: 0.99 | B15: 0 | C15: 0 | D15: 0 | E15: 0.31916788

Sheet EENS
A3: Sum of EENS | B3: Column Labels
A4: Row Labels | B4: envelope | C4: e-reserve | D4: stochastic | E4: conservative
A5: 0 | B5: 0 | C5: 0 | D5: 0 | E5: 0
A6: 0.1 | B6: 0 | C6: 0 | D6: 0 | E6: 0
A7: 0.2 | B7: 0.63745724 | C7: 0 | D7: 0 | E7: 0
A8: 0.3 | B8: 2.021744 | C8: 0 | D8: 0 | E8: 0
A9: 0.4 | B9: 0 | C9: 0 | D9: 0 | E9: 0
A10: 0.5 | B10: 0 | C10: 0 | D10: 0 | E10: 0
A11: 0.6 | B11: 0 | C11: 0 | D11: 0 | E11: 0
A12: 0.7 | B12: 0 | C12: 0 | D12: 0 | E12: 0
A13: 0.8 | B13: 0 | C13: 0 | D13: 0 | E13: 0
A14: 0.9 | B14: 0 | C14: 0 | D14: 0 | E14: 0
A15: 0.99 | B15: 0.62407091 | C15: 0 | D15: 0 | E15: 0
A21: Row Labels | B21: Sum of EENS
A22: 0 | B22: 0
A23: 0.1 | B23: 0
A24: 0.2 | B24: 0.63745724
A25: 0.3 | B25: 2.021744
A26: 0.4 | B26: 0
A27: 0.5 | B27: 0
A28: 0.6 | B28: 0
A29: 0.7 | B29: 0
A30: 0.8 | B30: 0
A31: 0.9 | B31: 0
A32: 0.99 | B32: 0.62407091
A33: Grand Total | B33: 3.2832722

Sheet EOPEX
A3: mu | B3: (All)
O4: Column Labels
B5: Column Labels | O5: Sum of EOPEX | S5: Sum of EENS_cost | W5: Sum of ELGEN_cost | AA5: Sum of EOPEX
A6: Row Labels | B6: 0 | C6: 0.1 | D6: 0.2 | E6: 0.3 | F6: 0.4 | G6: 0.5 | H6: 0.6 | I6: 0.7 | J6: 0.8 | K6: 0.9 | L6: 0.99 | N6: Row Labels | O6: envelope | P6: e-reserve | Q6: stochastic | R6: conservative | S6: envelope | T6: e-reserve | U6: stochastic | V6: conservative | W6: envelope | X6: e-reserve | Y6: stochastic | Z6: conservative | AA6: e-reserve>=envelope?
A7: Sum of E_start_cost | N7: 0 | O7: 800627.13 | P7: 800627.08 | Q7: 796469.72 | R7: 808058.21 | S7: 0 | T7: 0 | U7: 0 | V7: 0 | W7: 0 | X7: 0 | Y7: 0 | Z7: 0 | AA7: =ROUNDDOWN((GETPIVOTDATA("Sum of EOPEX",$N$4,"model_type","e-reserve","rho",N7)-GETPIVOTDATA("Sum of EOPEX",$N$4,"model_type","envelope","rho",N7))/GETPIVOTDATA("Sum of EOPEX",$N$4,"model_type","envelope","rho",N7),7)>=0 -> TRUE
A8: envelope | B8: 0 | C8: 0 | D8: 0 | E8: 0 | F8: 0 | G8: 0 | H8: 0 | I8: 0 | J8: 0 | K8: 0 | L8: 0 | N8: 0.1 | O8: 800160.25 | P8: 800079.35 | Q8: 795440.88 | R8: 807863.59 | S8: 0 | T8: 0 | U8: 0 | V8: 0 | W8: 0 | X8: 0 | Y8: 0 | Z8: 0 | AA8: =ROUNDDOWN((GETPIVOTDATA("Sum of EOPEX",$N$4,"model_type","e-reserve","rho",N8)-GETPIVOTDATA("Sum of EOPEX",$N$4,"model_type","envelope","rho",N8))/GETPIVOTDATA("Sum of EOPEX",$N$4,"model_type","envelope","rho",N8),7)>=0 -> FALSE
A9: e-reserve | B9: 0 | C9: 0 | D9: 0 | E9: 0 | F9: 0 | G9: 0 | H9: 0 | I9: 0 | J9: 0 | K9: 0 | L9: 0 | N9: 0.2 | O9: 800452.98 | P9: 800452.98 | Q9: 796642.79 | R9: 811588.96 | S9: 6374.5724 | T9: 0 | U9: 0 | V9: 0 | W9: 0 | X9: -8.6970431e-13 | Y9: 0 | Z9: 0 | AA9: =ROUNDDOWN((GETPIVOTDATA("Sum of EOPEX",$N$4,"model_type","e-reserve","rho",N9)-GETPIVOTDATA("Sum of EOPEX",$N$4,"model_type","envelope","rho",N9))/GETPIVOTDATA("Sum of EOPEX",$N$4,"model_type","envelope","rho",N9),7)>=0 -> TRUE
A10: stochastic | B10: 0 | C10: 0 | D10: 0 | E10: 0 | F10: 0 | G10: 0 | H10: 0 | I10: 0 | J10: 0 | K10: 0 | L10: 0 | N10: 0.3 | O10: 800411.44 | P10: 800411.44 | Q10: 796530.57 | R10: 808877.04 | S10: 20217.44 | T10: 0 | U10: 0 | V10: 0 | W10: 0 | X10: 0 | Y10: 0 | Z10: 0 | AA10: =ROUNDDOWN((GETPIVOTDATA("Sum of EOPEX",$N$4,"model_type","e-reserve","rho",N10)-GETPIVOTDATA("Sum of EOPEX",$N$4,"model_type","envelope","rho",N10))/GETPIVOTDATA("Sum of EOPEX",$N$4,"model_type","envelope","rho",N10),7)>=0 -> TRUE
A11: conservative | B11: 0 | C11: 0 | D11: 0 | E11: 0 | F11: 0 | G11: 0 | H11: 0 | I11: 0 | J11: 0 | K11: 0 | L11: 0 | N11: 0.4 | O11: 800162.66 | P11: 800162.66 | Q11: 795701.56 | R11: 807195.26 | S11: 0 | T11: 0 | U11: 0 | V11: 0 | W11: 0 | X11: 0 | Y11: 0 | Z11: 0 | AA11: =ROUNDDOWN((GETPIVOTDATA("Sum of EOPEX",$N$4,"model_type","e-reserve","rho",N11)-GETPIVOTDATA("Sum of EOPEX",$N$4,"model_type","envelope","rho",N11))/GETPIVOTDATA("Sum of EOPEX",$N$4,"model_type","envelope","rho",N11),7)>=0 -> TRUE
A12: Sum of E_production_cost | N12: 0.5 | O12: 800062.59 | P12: 800062.59 | Q12: 795008.52 | R12: 814114 | S12: 0 | T12: 0 | U12: 0 | V12: 0 | W12: 0 | X12: 0 | Y12: 0 | Z12: 0 | AA12: =ROUNDDOWN((GETPIVOTDATA("Sum of EOPEX",$N$4,"model_type","e-reserve","rho",N12)-GETPIVOTDATA("Sum of EOPEX",$N$4,"model_type","envelope","rho",N12))/GETPIVOTDATA("Sum of EOPEX",$N$4,"model_type","envelope","rho",N12),7)>=0 -> TRUE
A13: envelope | B13: 749411.59 | C13: 748944.71 | D13: 749237.45 | E13: 749195.9 | F13: 748947.12 | G13: 748847.05 | H13: 749383.35 | I13: 750345.42 | J13: 751496.75 | K13: 749164.6 | L13: 748682.66 | N13: 0.6 | O13: 800598.89 | P13: 802691.46 | Q13: 796231.63 | R13: 810987.91 | S13: 0 | T13: 0 | U13: 0 | V13: 0 | W13: 0 | X13: 0 | Y13: 0 | Z13: 0 | AA13: =ROUNDDOWN((GETPIVOTDATA("Sum of EOPEX",$N$4,"model_type","e-reserve","rho",N13)-GETPIVOTDATA("Sum of EOPEX",$N$4,"model_type","envelope","rho",N13))/GETPIVOTDATA("Sum of EOPEX",$N$4,"model_type","envelope","rho",N13),7)>=0 -> TRUE
A14: e-reserve | B14: 749411.54 | C14: 749141.21 | D14: 749237.45 | E14: 749195.9 | F14: 748947.12 | G14: 748847.05 | H14: 750261.77 | I14: 751023.55 | J14: 749481.18 | K14: 749262.02 | L14: 748711.89 | N14: 0.7 | O14: 802775.11 | P14: 803581.04 | Q14: 795787.74 | R14: 807595.44 | S14: 0 | T14: 0 | U14: 0 | V14: 0 | W14: 0 | X14: 0 | Y14: 0 | Z14: 0 | AA14: =ROUNDDOWN((GETPIVOTDATA("Sum of EOPEX",$N$4,"model_type","e-reserve","rho",N14)-GETPIVOTDATA("Sum of EOPEX",$N$4,"model_type","envelope","rho",N14))/GETPIVOTDATA("Sum of EOPEX",$N$4,"model_type","envelope","rho",N14),7)>=0 -> TRUE
A15: stochastic | B15: 745254.18 | C15: 744225.34 | D15: 745427.25 | E15: 745315.03 | F15: 744486.03 | G15: 743792.98 | H15: 745016.09 | I15: 744572.2 | J15: 745051.81 | K15: 745956.51 | L15: 747580.52 | N15: 0.8 | O15: 804182.05 | P15: 805872.16 | Q15: 796267.35 | R15: 807664.97 | S15: 0 | T15: 0 | U15: 0 | V15: 0 | W15: 0 | X15: 0 | Y15: 646.1977 | Z15: 0 | AA15: =ROUNDDOWN((GETPIVOTDATA("Sum of EOPEX",$N$4,"model_type","e-reserve","rho",N15)-GETPIVOTDATA("Sum of EOPEX",$N$4,"model_type","envelope","rho",N15))/GETPIVOTDATA("Sum of EOPEX",$N$4,"model_type","envelope","rho",N15),7)>=0 -> TRUE
A16: conservative | B16: 750571.9 | C16: 750649.92 | D16: 754102.65 | E16: 751390.74 | F16: 749981.6 | G16: 756900.34 | H16: 753774.25 | I16: 750381.77 | J16: 750178.67 | K16: 756406.52 | L16: 748768.22 | N16: 0.9 | O16: 805560.34 | P16: 805930.4 | Q16: 798514 | R16: 813620.18 | S16: 0 | T16: 0 | U16: 0 | V16: 0 | W16: 0 | X16: 0 | Y16: 324.704 | Z16: 0 | AA16: =ROUNDDOWN((GETPIVOTDATA("Sum of EOPEX",$N$4,"model_type","e-reserve","rho",N16)-GETPIVOTDATA("Sum of EOPEX",$N$4,"model_type","envelope","rho",N16))/GETPIVOTDATA("Sum of EOPEX",$N$4,"model_type","envelope","rho",N16),7)>=0 -> TRUE
A17: Sum of E_fixed_cost | N17: 0.99 | O17: 805351.04 | P17: 805380.27 | Q17: 800265.81 | R17: 805431.84 | S17: 6240.7091 | T17: 0 | U17: 0 | V17: 0 | W17: 0 | X17: 0 | Y17: 319.16788 | Z17: 0 | AA17: =ROUNDDOWN((GETPIVOTDATA("Sum of EOPEX",$N$4,"model_type","e-reserve","rho",N17)-GETPIVOTDATA("Sum of EOPEX",$N$4,"model_type","envelope","rho",N17))/GETPIVOTDATA("Sum of EOPEX",$N$4,"model_type","envelope","rho",N17),7)>=0 -> TRUE
A18: envelope | B18: 51215.538 | C18: 51215.538 | D18: 51215.538 | E18: 51215.538 | F18: 51215.538 | G18: 51215.538 | H18: 51215.538 | I18: 52429.688 | J18: 52685.299 | K18: 56395.736 | L18: 56668.378
A19: e-reserve | B19: 51215.538 | C19: 50938.14 | D19: 51215.538 | E19: 51215.538 | F19: 51215.538 | G19: 51215.538 | H19: 52429.688 | I19: 52557.493 | J19: 56390.979 | K19: 56668.378 | L19: 56668.378
A20: stochastic | B20: 51215.538 | C20: 51215.538 | D20: 51215.538 | E20: 51215.538 | F20: 51215.538 | G20: 51215.538 | H20: 51215.538 | I20: 51215.538 | J20: 51215.538 | K20: 52557.493 | L20: 52685.299 | N20: Sum of E_production_cost | O20: Column Labels
A21: conservative | B21: 57486.304 | C21: 57213.662 | D21: 57486.304 | E21: 57486.304 | F21: 57213.662 | G21: 57213.662 | H21: 57213.662 | I21: 57213.662 | J21: 57486.304 | K21: 57213.662 | L21: 56663.621 | N21: Row Labels | O21: conservative | P21: envelope | Q21: e-reserve | R21: stochastic | S21: e-reserve>=envelope | T21: envelope-stochastic | U21: e-reserve-stochastic
A22: Sum of EOV | N22: 0 | O22: 750571.9 | P22: 749411.59 | Q22: 749411.54 | R22: 745254.18 | S22: =ROUND((GETPIVOTDATA("E_production_cost",$N$20,"model_type","e-reserve","rho",N22)-GETPIVOTDATA("E_production_cost",$N$20,"model_type","envelope","rho",N22))/GETPIVOTDATA("E_production_cost",$N$20,"model_type","envelope","rho",N22),8)>=0 -> FALSE | T22: =GETPIVOTDATA("E_production_cost",$N$20,"model_type","envelope","rho",N22)-GETPIVOTDATA("E_production_cost",$N$20,"model_type","stochastic","rho",N22) -> 4157.4054 | U22: =GETPIVOTDATA("E_production_cost",$N$20,"model_type","e-reserve","rho",N22)-GETPIVOTDATA("E_production_cost",$N$20,"model_type","stochastic","rho",N22) -> 4157.3622
A23: envelope | B23: 800627.14 | C23: 800160.26 | D23: 806827.57 | E23: 820628.89 | F23: 800162.67 | G23: 800062.6 | H23: 800598.9 | I23: 802775.12 | J23: 804182.06 | K23: 805560.35 | L23: 811591.75 | N23: 0.1 | O23: 750649.92 | P23: 748944.71 | Q23: 749141.21 | R23: 744225.34 | S23: =ROUND((GETPIVOTDATA("E_production_cost",$N$20,"model_type","e-reserve","rho",N23)-GETPIVOTDATA("E_production_cost",$N$20,"model_type","envelope","rho",N23))/GETPIVOTDATA("E_production_cost",$N$20,"model_type","envelope","rho",N23),8)>=0 -> TRUE | T23: =GETPIVOTDATA("E_production_cost",$N$20,"model_type","envelope","rho",N23)-GETPIVOTDATA("E_production_cost",$N$20,"model_type","stochastic","rho",N23) -> 4719.3702 | U23: =GETPIVOTDATA("E_production_cost",$N$20,"model_type","e-reserve","rho",N23)-GETPIVOTDATA("E_production_cost",$N$20,"model_type","stochastic","rho",N23) -> 4915.8721
A24: e-reserve | B24: 800627.09 | C24: 800079.36 | D24: 800452.99 | E24: 800411.45 | F24: 800162.67 | G24: 800062.6 | H24: 802691.47 | I24: 803581.05 | J24: 805872.17 | K24: 805930.41 | L24: 805380.28 | N24: 0.2 | O24: 754102.65 | P24: 749237.45 | Q24: 749237.45 | R24: 745427.25 | S24: =ROUND((GETPIVOTDATA("E_production_cost",$N$20,"model_type","e-reserve","rho",N24)-GETPIVOTDATA("E_production_cost",$N$20,"model_type","envelope","rho",N24))/GETPIVOTDATA("E_production_cost",$N$20,"model_type","envelope","rho",N24),8)>=0 -> TRUE | T24: =GETPIVOTDATA("E_production_cost",$N$20,"model_type","envelope","rho",N24)-GETPIVOTDATA("E_production_cost",$N$20,"model_type","stochastic","rho",N24) -> 3810.1971 | U24: =GETPIVOTDATA("E_production_cost",$N$20,"model_type","e-reserve","rho",N24)-GETPIVOTDATA("E_production_cost",$N$20,"model_type","stochastic","rho",N24) -> 3810.1971
A25: stochastic | B25: 796469.72 | C25: 795440.88 | D25: 796642.79 | E25: 796530.57 | F25: 795701.56 | G25: 795008.52 | H25: 796231.63 | I25: 795787.74 | J25: 796913.55 | K25: 798838.71 | L25: 800584.98 | M25: =GETPIVOTDATA("Sum of EOPEX",$A$5,"model_type","stochastic","rho",0.8)+GETPIVOTDATA("Sum of ELGEN_cost",$A$5,"model_type","stochastic","rho",0.8) -> 796913.55 | N25: 0.3 | O25: 751390.74 | P25: 749195.9 | Q25: 749195.9 | R25: 745315.03 | S25: =ROUND((GETPIVOTDATA("E_production_cost",$N$20,"model_type","e-reserve","rho",N25)-GETPIVOTDATA("E_production_cost",$N$20,"model_type","envelope","rho",N25))/GETPIVOTDATA("E_production_cost",$N$20,"model_type","envelope","rho",N25),8)>=0 -> TRUE | T25: =GETPIVOTDATA("E_production_cost",$N$20,"model_type","envelope","rho",N25)-GETPIVOTDATA("E_production_cost",$N$20,"model_type","stochastic","rho",N25) -> 3880.8652 | U25: =GETPIVOTDATA("E_production_cost",$N$20,"model_type","e-reserve","rho",N25)-GETPIVOTDATA("E_production_cost",$N$20,"model_type","stochastic","rho",N25) -> 3880.8652
A26: conservative | B26: 808058.22 | C26: 807863.6 | D26: 811588.97 | E26: 808877.05 | F26: 807195.27 | G26: 814114.01 | H26: 810987.92 | I26: 807595.45 | J26: 807664.98 | K26: 813620.19 | L26: 805431.85 | N26: 0.4 | O26: 749981.6 | P26: 748947.12 | Q26: 748947.12 | R26: 744486.03 | S26: =ROUND((GETPIVOTDATA("E_production_cost",$N$20,"model_type","e-reserve","rho",N26)-GETPIVOTDATA("E_production_cost",$N$20,"model_type","envelope","rho",N26))/GETPIVOTDATA("E_production_cost",$N$20,"model_type","envelope","rho",N26),8)>=0 -> TRUE | T26: =GETPIVOTDATA("E_production_cost",$N$20,"model_type","envelope","rho",N26)-GETPIVOTDATA("E_production_cost",$N$20,"model_type","stochastic","rho",N26) -> 4461.0966 | U26: =GETPIVOTDATA("E_production_cost",$N$20,"model_type","e-reserve","rho",N26)-GETPIVOTDATA("E_production_cost",$N$20,"model_type","stochastic","rho",N26) -> 4461.0966
A27: Sum of EOPEX | N27: 0.5 | O27: 756900.34 | P27: 748847.05 | Q27: 748847.05 | R27: 743792.98 | S27: =ROUND((GETPIVOTDATA("E_production_cost",$N$20,"model_type","e-reserve","rho",N27)-GETPIVOTDATA("E_production_cost",$N$20,"model_type","envelope","rho",N27))/GETPIVOTDATA("E_production_cost",$N$20,"model_type","envelope","rho",N27),8)>=0 -> TRUE | T27: =GETPIVOTDATA("E_production_cost",$N$20,"model_type","envelope","rho",N27)-GETPIVOTDATA("E_production_cost",$N$20,"model_type","stochastic","rho",N27) -> 5054.0679 | U27: =GETPIVOTDATA("E_production_cost",$N$20,"model_type","e-reserve","rho",N27)-GETPIVOTDATA("E_production_cost",$N$20,"model_type","stochastic","rho",N27) -> 5054.0679
A28: envelope | B28: 800627.13 | C28: 800160.25 | D28: 800452.98 | E28: 800411.44 | F28: 800162.66 | G28: 800062.59 | H28: 800598.89 | I28: 802775.11 | J28: 804182.05 | K28: 805560.34 | L28: 805351.04 | N28: 0.6 | O28: 753774.25 | P28: 749383.35 | Q28: 750261.77 | R28: 745016.09 | S28: =ROUND((GETPIVOTDATA("E_production_cost",$N$20,"model_type","e-reserve","rho",N28)-GETPIVOTDATA("E_production_cost",$N$20,"model_type","envelope","rho",N28))/GETPIVOTDATA("E_production_cost",$N$20,"model_type","envelope","rho",N28),8)>=0 -> TRUE | T28: =GETPIVOTDATA("E_production_cost",$N$20,"model_type","envelope","rho",N28)-GETPIVOTDATA("E_production_cost",$N$20,"model_type","stochastic","rho",N28) -> 4367.2613 | U28: =GETPIVOTDATA("E_production_cost",$N$20,"model_type","e-reserve","rho",N28)-GETPIVOTDATA("E_production_cost",$N$20,"model_type","stochastic","rho",N28) -> 5245.6805
A29: e-reserve | B29: 800627.08 | C29: 800079.35 | D29: 800452.98 | E29: 800411.44 | F29: 800162.66 | G29: 800062.59 | H29: 802691.46 | I29: 803581.04 | J29: 805872.16 | K29: 805930.4 | L29: 805380.27 | N29: 0.7 | O29: 750381.77 | P29: 750345.42 | Q29: 751023.55 | R29: 744572.2 | S29: =ROUND((GETPIVOTDATA("E_production_cost",$N$20,"model_type","e-reserve","rho",N29)-GETPIVOTDATA("E_production_cost",$N$20,"model_type","envelope","rho",N29))/GETPIVOTDATA("E_production_cost",$N$20,"model_type","envelope","rho",N29),8)>=0 -> TRUE | T29: =GETPIVOTDATA("E_production_cost",$N$20,"model_type","envelope","rho",N29)-GETPIVOTDATA("E_production_cost",$N$20,"model_type","stochastic","rho",N29) -> 5773.2208 | U29: =GETPIVOTDATA("E_production_cost",$N$20,"model_type","e-reserve","rho",N29)-GETPIVOTDATA("E_production_cost",$N$20,"model_type","stochastic","rho",N29) -> 6451.3477
A30: stochastic | B30: 796469.72 | C30: 795440.88 | D30: 796642.79 | E30: 796530.57 | F30: 795701.56 | G30: 795008.52 | H30: 796231.63 | I30: 795787.74 | J30: 796267.35 | K30: 798514 | L30: 800265.81 | N30: 0.8 | O30: 750178.67 | P30: 751496.75 | Q30: 749481.18 | R30: 745051.81 | S30: =ROUND((GETPIVOTDATA("E_production_cost",$N$20,"model_type","e-reserve","rho",N30)-GETPIVOTDATA("E_production_cost",$N$20,"model_type","envelope","rho",N30))/GETPIVOTDATA("E_production_cost",$N$20,"model_type","envelope","rho",N30),8)>=0 -> FALSE | T30: =GETPIVOTDATA("E_production_cost",$N$20,"model_type","envelope","rho",N30)-GETPIVOTDATA("E_production_cost",$N$20,"model_type","stochastic","rho",N30) -> 6444.9374 | U30: =GETPIVOTDATA("E_production_cost",$N$20,"model_type","e-reserve","rho",N30)-GETPIVOTDATA("E_production_cost",$N$20,"model_type","stochastic","rho",N30) -> 4429.3698
A31: conservative | B31: 808058.21 | C31: 807863.59 | D31: 811588.96 | E31: 808877.04 | F31: 807195.26 | G31: 814114 | H31: 810987.91 | I31: 807595.44 | J31: 807664.97 | K31: 813620.18 | L31: 805431.84 | N31: 0.9 | O31: 756406.52 | P31: 749164.6 | Q31: 749262.02 | R31: 745956.51 | S31: =ROUND((GETPIVOTDATA("E_production_cost",$N$20,"model_type","e-reserve","rho",N31)-GETPIVOTDATA("E_production_cost",$N$20,"model_type","envelope","rho",N31))/GETPIVOTDATA("E_production_cost",$N$20,"model_type","envelope","rho",N31),8)>=0 -> TRUE | T31: =GETPIVOTDATA("E_production_cost",$N$20,"model_type","envelope","rho",N31)-GETPIVOTDATA("E_production_cost",$N$20,"model_type","stochastic","rho",N31) -> 3208.0927 | U31: =GETPIVOTDATA("E_production_cost",$N$20,"model_type","e-reserve","rho",N31)-GETPIVOTDATA("E_production_cost",$N$20,"model_type","stochastic","rho",N31) -> 3305.5132
A32: Sum of EENS_cost | N32: 0.99 | O32: 748768.22 | P32: 748682.66 | Q32: 748711.89 | R32: 747580.52 | S32: =ROUND((GETPIVOTDATA("E_production_cost",$N$20,"model_type","e-reserve","rho",N32)-GETPIVOTDATA("E_production_cost",$N$20,"model_type","envelope","rho",N32))/GETPIVOTDATA("E_production_cost",$N$20,"model_type","envelope","rho",N32),8)>=0 -> TRUE | T32: =GETPIVOTDATA("E_production_cost",$N$20,"model_type","envelope","rho",N32)-GETPIVOTDATA("E_production_cost",$N$20,"model_type","stochastic","rho",N32) -> 1102.1414 | U32: =GETPIVOTDATA("E_production_cost",$N$20,"model_type","e-reserve","rho",N32)-GETPIVOTDATA("E_production_cost",$N$20,"model_type","stochastic","rho",N32) -> 1131.3785
A33: envelope | B33: 0 | C33: 0 | D33: 6374.5724 | E33: 20217.44 | F33: 0 | G33: 0 | H33: 0 | I33: 0 | J33: 0 | K33: 0 | L33: 6240.7091
A34: e-reserve | B34: 0 | C34: 0 | D34: 0 | E34: 0 | F34: 0 | G34: 0 | H34: 0 | I34: 0 | J34: 0 | K34: 0 | L34: 0
A35: stochastic | B35: 0 | C35: 0 | D35: 0 | E35: 0 | F35: 0 | G35: 0 | H35: 0 | I35: 0 | J35: 0 | K35: 0 | L35: 0 | N35: Sum of E_fixed_cost | O35: Column Labels
A36: conservative | B36: 0 | C36: 0 | D36: 0 | E36: 0 | F36: 0 | G36: 0 | H36: 0 | I36: 0 | J36: 0 | K36: 0 | L36: 0 | N36: Row Labels | O36: conservative | P36: envelope | Q36: e-reserve | R36: stochastic | S36: e-reserve>=envelope
A37: Sum of ELGEN_cost | N37: 0 | O37: 57486.304 | P37: 51215.538 | Q37: 51215.538 | R37: 51215.538 | S37: =ROUND((GETPIVOTDATA("Sum of E_fixed_cost",$N$35,"model_type","e-reserve","rho",N37)-GETPIVOTDATA("Sum of E_fixed_cost",$N$35,"model_type","envelope","rho",N37))/GETPIVOTDATA("Sum of E_fixed_cost",$N$35,"model_type","envelope","rho",N37),8)>=0 -> TRUE
A38: envelope | B38: 0 | C38: 0 | D38: 0 | E38: 0 | F38: 0 | G38: 0 | H38: 0 | I38: 0 | J38: 0 | K38: 0 | L38: 0 | N38: 0.1 | O38: 57213.662 | P38: 51215.538 | Q38: 50938.14 | R38: 51215.538 | S38: =ROUND((GETPIVOTDATA("Sum of E_fixed_cost",$N$35,"model_type","e-reserve","rho",N38)-GETPIVOTDATA("Sum of E_fixed_cost",$N$35,"model_type","envelope","rho",N38))/GETPIVOTDATA("Sum of E_fixed_cost",$N$35,"model_type","envelope","rho",N38),8)>=0 -> FALSE
A39: e-reserve | B39: 0 | C39: 0 | D39: -8.6970431e-13 | E39: 0 | F39: 0 | G39: 0 | H39: 0 | I39: 0 | J39: 0 | K39: 0 | L39: 0 | N39: 0.2 | O39: 57486.304 | P39: 51215.538 | Q39: 51215.538 | R39: 51215.538 | S39: =ROUND((GETPIVOTDATA("Sum of E_fixed_cost",$N$35,"model_type","e-reserve","rho",N39)-GETPIVOTDATA("Sum of E_fixed_cost",$N$35,"model_type","envelope","rho",N39))/GETPIVOTDATA("Sum of E_fixed_cost",$N$35,"model_type","envelope","rho",N39),8)>=0 -> TRUE
A40: stochastic | B40: 0 | C40: 0 | D40: 0 | E40: 0 | F40: 0 | G40: 0 | H40: 0 | I40: 0 | J40: 646.1977 | K40: 324.704 | L40: 319.16788 | N40: 0.3 | O40: 57486.304 | P40: 51215.538 | Q40: 51215.538 | R40: 51215.538 | S40: =ROUND((GETPIVOTDATA("Sum of E_fixed_cost",$N$35,"model_type","e-reserve","rho",N40)-GETPIVOTDATA("Sum of E_fixed_cost",$N$35,"model_type","envelope","rho",N40))/GETPIVOTDATA("Sum of E_fixed_cost",$N$35,"model_type","envelope","rho",N40),8)>=0 -> TRUE
A41: conservative | B41: 0 | C41: 0 | D41: 0 | E41: 0 | F41: 0 | G41: 0 | H41: 0 | I41: 0 | J41: 0 | K41: 0 | L41: 0 | N41: 0.4 | O41: 57213.662 | P41: 51215.538 | Q41: 51215.538 | R41: 51215.538 | S41: =ROUND((GETPIVOTDATA("Sum of E_fixed_cost",$N$35,"model_type","e-reserve","rho",N41)-GETPIVOTDATA("Sum of E_fixed_cost",$N$35,"model_type","envelope","rho",N41))/GETPIVOTDATA("Sum of E_fixed_cost",$N$35,"model_type","envelope","rho",N41),8)>=0 -> TRUE
A42: Sum of reserve_cost_uc | N42: 0.5 | O42: 57213.662 | P42: 51215.538 | Q42: 51215.538 | R42: 51215.538 | S42: =ROUND((GETPIVOTDATA("Sum of E_fixed_cost",$N$35,"model_type","e-reserve","rho",N42)-GETPIVOTDATA("Sum of E_fixed_cost",$N$35,"model_type","envelope","rho",N42))/GETPIVOTDATA("Sum of E_fixed_cost",$N$35,"model_type","envelope","rho",N42),8)>=0 -> TRUE
...

Sheet EOPEX2
A3: Row Labels | B3: Sum of E_fixed_cost | C3: Sum of E_production_cost | D3: Sum of EENS_cost | E3: Sum of ELGEN_cost | F3: Envelope> | L3: Row Labels | M3: Sum of EENS_cost | N3: Sum of ELGEN_cost
A4: 0 | B4: 211132.92 | C4: 2994649.2 | D4: 0 | E4: 0 | L4: 0 | M4: 0 | N4: 0
A5: stochastic | B5: 51215.538 | C5: 745254.18 | D5: 0 | E5: 0 | L5: stochastic | M5: 0 | N5: 0
A6: e-reserve | B6: 51215.538 | C6: 749411.54 | D6: 0 | E6: 0 | L6: e-reserve | M6: 0 | N6: 0
A7: envelope | B7: 51215.538 | C7: 749411.59 | D7: 0 | E7: 0 | G7: =GETPIVOTDATA("Sum of E_fixed_cost",$A$3,"model_type",$A6,"rho",$A4)-GETPIVOTDATA("Sum of E_fixed_cost",$A$3,"model_type",$A7,"rho",$A4) -> 0 | H7: =GETPIVOTDATA("Sum of E_production_cost",$A$3,"model_type",$A6,"rho",$A4)-GETPIVOTDATA("Sum of E_production_cost",$A$3,"model_type",$A7,"rho",$A4) -> -0.043138479 | L7: envelope | M7: 0 | N7: 0
A8: conservative | B8: 57486.304 | C8: 750571.9 | D8: 0 | E8: 0 | L8: conservative | M8: 0 | N8: 0
A9: 0.1 | B9: 210582.88 | C9: 2992961.2 | D9: 0 | E9: 0 | L9: 0.1 | M9: 0 | N9: 0
A10: stochastic | B10: 51215.538 | C10: 744225.34 | D10: 0 | E10: 0 | L10: stochastic | M10: 0 | N10: 0
A11: e-reserve | B11: 50938.14 | C11: 749141.21 | D11: 0 | E11: 0 | L11: e-reserve | M11: 0 | N11: 0
A12: envelope | B12: 51215.538 | C12: 748944.71 | D12: 0 | E12: 0 | G12: =GETPIVOTDATA("Sum of E_fixed_cost",$A$3,"model_type",A11,"rho",A9)-GETPIVOTDATA("Sum of E_fixed_cost",$A$3,"model_type",A12,"rho",A9) -> -277.39852 | H12: =GETPIVOTDATA("Sum of E_production_cost",$A$3,"model_type",$A11,"rho",$A9)-GETPIVOTDATA("Sum of E_production_cost",$A$3,"model_type",$A12,"rho",$A9) -> 196.50192 | L12: envelope | M12: 0 | N12: 0
A13: conservative | B13: 57213.662 | C13: 750649.92 | D13: 0 | E13: 0 | L13: conservative | M13: 0 | N13: 0
A14: 0.2 | B14: 211132.92 | C14: 2998004.8 | D14: 6374.5724 | E14: -8.6970431e-13 | L14: 0.2 | M14: 6374.5724 | N14: -8.6970431e-13
A15: stochastic | B15: 51215.538 | C15: 745427.25 | D15: 0 | E15: 0 | L15: stochastic | M15: 0 | N15: 0
A16: e-reserve | B16: 51215.538 | C16: 749237.45 | D16: 0 | E16: -8.6970431e-13 | L16: e-reserve | M16: 0 | N16: -8.6970431e-13
A17: envelope | B17: 51215.538 | C17: 749237.45 | D17: 6374.5724 | E17: 0 | G17: =GETPIVOTDATA("Sum of E_fixed_cost",$A$3,"model_type",A16,"rho",A14)-GETPIVOTDATA("Sum of E_fixed_cost",$A$3,"model_type",A17,"rho",A14) -> 0 | H17: =GETPIVOTDATA("Sum of E_production_cost",$A$3,"model_type",$A16,"rho",$A14)-GETPIVOTDATA("Sum of E_production_cost",$A$3,"model_type",$A17,"rho",$A14) -> 3.2398384e-07 | L17: envelope | M17: 6374.5724 | N17: 0
A18: conservative | B18: 57486.304 | C18: 754102.65 | D18: 0 | E18: 0 | L18: conservative | M18: 0 | N18: 0
A19: 0.3 | B19: 211132.92 | C19: 2995097.6 | D19: 20217.44 | E19: 0 | L19: 0.3 | M19: 20217.44 | N19: 0
A20: stochastic | B20: 51215.538 | C20: 745315.03 | D20: 0 | E20: 0 | L20: stochastic | M20: 0 | N20: 0
A21: e-reserve | B21: 51215.538 | C21: 749195.9 | D21: 0 | E21: 0 | L21: e-reserve | M21: 0 | N21: 0
A22: envelope | B22: 51215.538 | C22: 749195.9 | D22: 20217.44 | E22: 0 | G22: =GETPIVOTDATA("Sum of E_fixed_cost",$A$3,"model_type",A21,"rho",A19)-GETPIVOTDATA("Sum of E_fixed_cost",$A$3,"model_type",A22,"rho",A19) -> 0 | H22: =GETPIVOTDATA("Sum of E_production_cost",$A$3,"model_type",$A21,"rho",$A19)-GETPIVOTDATA("Sum of E_production_cost",$A$3,"model_type",$A22,"rho",$A19) -> -5.1179668e-06 | L22: envelope | M22: 20217.44 | N22: 0
A23: conservative | B23: 57486.304 | C23: 751390.74 | D23: 0 | E23: 0 | L23: conservative | M23: 0 | N23: 0
A24: 0.4 | B24: 210860.28 | C24: 2992361.9 | D24: 0 | E24: 0 | L24: 0.4 | M24: 0 | N24: 0
A25: stochastic | B25: 51215.538 | C25: 744486.03 | D25: 0 | E25: 0 | L25: stochastic | M25: 0 | N25: 0
A26: e-reserve | B26: 51215.538 | C26: 748947.12 | D26: 0 | E26: 0 | L26: e-reserve | M26: 0 | N26: 0
A27: envelope | B27: 51215.538 | C27: 748947.12 | D27: 0 | E27: 0 | G27: =GETPIVOTDATA("Sum of E_fixed_cost",$A$3,"model_type",A26,"rho",A24)-GETPIVOTDATA("Sum of E_fixed_cost",$A$3,"model_type",A27,"rho",A24) -> 0 | H27: =GETPIVOTDATA("Sum of E_production_cost",$A$3,"model_type",$A26,"rho",$A24)-GETPIVOTDATA("Sum of E_production_cost",$A$3,"model_type",$A27,"rho",$A24) -> 2.0740554e-06 | L27: envelope | M27: 0 | N27: 0
A28: conservative | B28: 57213.662 | C28: 749981.6 | D28: 0 | E28: 0 | L28: conservative | M28: 0 | N28: 0
A29: 0.5 | B29: 210860.28 | C29: 2998387.4 | D29: 0 | E29: 0 | L29: 0.5 | M29: 0 | N29: 0
A30: stochastic | B30: 51215.538 | C30: 743792.98 | D30: 0 | E30: 0 | L30: stochastic | M30: 0 | N30: 0
A31: e-reserve | B31: 51215.538 | C31: 748847.05 | D31: 0 | E31: 0 | L31: e-reserve | M31: 0 | N31: 0
A32: envelope | B32: 51215.538 | C32: 748847.05 | D32: 0 | E32: 0 | G32: =GETPIVOTDATA("Sum of E_fixed_cost",$A$3,"model_type",A31,"rho",A29)-GETPIVOTDATA("Sum of E_fixed_cost",$A$3,"model_type",A32,"rho",A29) -> 0 | H32: =GETPIVOTDATA("Sum of E_production_cost",$A$3,"model_type",$A31,"rho",$A29)-GETPIVOTDATA("Sum of E_production_cost",$A$3,"model_type",$A32,"rho",$A29) -> -8.7539665e-06 | L32: envelope | M32: 0 | N32: 0
A33: conservative | B33: 57213.662 | C33: 756900.34 | D33: 0 | E33: 0 | L33: conservative | M33: 0 | N33: 0
A34: 0.6 | B34: 212074.43 | C34: 2998435.5 | D34: 0 | E34: 0 | L34: 0.6 | M34: 0 | N34: 0
A35: stochastic | B35: 51215.538 | C35: 745016.09 | D35: 0 | E35: 0 | L35: stochastic | M35: 0 | N35: 0
A36: e-reserve | B36: 52429.688 | C36: 750261.77 | D36: 0 | E36: 0 | L36: e-reserve | M36: 0 | N36: 0
A37: envelope | B37: 51215.538 | C37: 749383.35 | D37: 0 | E37: 0 | G37: =GETPIVOTDATA("Sum of E_fixed_cost",$A$3,"model_type",A36,"rho",A34)-GETPIVOTDATA("Sum of E_fixed_cost",$A$3,"model_type",A37,"rho",A34) -> 1214.1499 | H37: =GETPIVOTDATA("Sum of E_production_cost",$A$3,"model_type",$A36,"rho",$A34)-GETPIVOTDATA("Sum of E_production_cost",$A$3,"model_type",$A37,"rho",$A34) -> 878.41926 | L37: envelope | M37: 0 | N37: 0
A38: conservative | B38: 57213.662 | C38: 753774.25 | D38: 0 | E38: 0 | L38: conservative | M38: 0 | N38: 0
A39: 0.7 | B39: 213416.38 | C39: 2996322.9 | D39: 0 | E39: 0 | L39: 0.7 | M39: 0 | N39: 0
A40: stochastic | B40: 51215.538 | C40: 744572.2 | D40: 0 | E40: 0 | L40: stochastic | M40: 0 | N40: 0
A41: e-reserve | B41: 52557.493 | C41: 751023.55 | D41: 0 | E41: 0 | L41: e-reserve | M41: 0 | N41: 0
A42: envelope | B42: 52429.688 | C42: 750345.42 | D42: 0 | E42: 0 | G42: =GETPIVOTDATA("Sum of E_fixed_cost",$A$3,"model_type",A41,"rho",A39)-GETPIVOTDATA("Sum of E_fixed_cost",$A$3,"model_type",A42,"rho",A39) -> 127.80525 | H42: =GETPIVOTDATA("Sum of E_production_cost",$A$3,"model_type",$A41,"rho",$A39)-GETPIVOTDATA("Sum of E_production_cost",$A$3,"model_type",$A42,"rho",$A39) -> 678.12688 | L42: envelope | M42: 0 | N42: 0
...

Sheet supply demand
B3: Column Labels
A4: Row Labels | B4: 0 | C4: 0.1 | D4: 0.2 | E4: 0.3 | F4: 0.4 | G4: 0.5 | H4: 0.6 | I4: 0.7 | J4: 0.8 | K4: 0.9 | L4: 0.99 | P4: Column Labels
A5: Sum of E_thermal_production_MWh | O5: Row Labels | P5: envelope | Q5: e-reserve | R5: stochastic | S5: conservative
A6: envelope | B6: 31857.027 | C6: 31876.855 | D6: 31862.389 | E6: 31863.944 | F6: 31877.082 | G6: 31884.485 | H6: 31861.277 | I6: 31869.171 | J6: 31879.576 | K6: 31872.409 | L6: 31939.636 | O6: Sum of E_thermal_production_MWh
A7: e-reserve | B7: 31857.026 | C7: 31883.112 | D7: 31862.389 | E7: 31863.944 | F7: 31877.082 | G7: 31884.485 | H7: 31875.895 | I7: 31869.171 | J7: 31864.958 | K7: 31872.409 | L7: 31940.094 | O7: 0.5 | P7: 31884.485 | Q7: 31884.485 | R7: 31720.752 | S7: 32103.963
A8: stochastic | B8: 31718.769 | C8: 31723.467 | D8: 31717.906 | E8: 31736.447 | F8: 31732.749 | G8: 31720.752 | H8: 31703.055 | I8: 31661.603 | J8: 31715.111 | K8: 31724.385 | L8: 31826.337 | O8: 0.8 | P8: 31879.576 | Q8: 31864.958 | R8: 31715.111 | S8: 31818.698
A9: conservative | B9: 31805.071 | C9: 31814.511 | D9: 31830.209 | E9: 31768.466 | F9: 31826.831 | G9: 32103.963 | H9: 31943.469 | I9: 31804.596 | J9: 31818.698 | K9: 32094.741 | L9: 31939.636 | O9: 0.99 | P9: 31939.636 | Q9: 31940.094 | R9: 31826.337 | S9: 31939.636
A10: Sum of E_nonRES_nonThermal_production_MWh | O10: Sum of E_storage_discharge_MWh
A11: envelope | B11: 1522.44 | C11: 1522.44 | D11: 1522.44 | E11: 1522.44 | F11: 1522.44 | G11: 1522.44 | H11: 1522.44 | I11: 1522.44 | J11: 1522.44 | K11: 1522.44 | L11: 1522.44 | O11: 0.5 | P11: 5569.878 | Q11: 5526.1092 | R11: 5636.9777 | S11: 5199.1736
A12: e-reserve | B12: 1522.44 | C12: 1522.44 | D12: 1522.44 | E12: 1522.44 | F12: 1522.44 | G12: 1522.44 | H12: 1522.44 | I12: 1522.44 | J12: 1522.44 | K12: 1522.44 | L12: 1522.44 | O12: 0.8 | P12: 5511.1867 | Q12: 5243.6607 | R12: 5597.3612 | S12: 5075.3201
A13: stochastic | B13: 1522.44 | C13: 1522.44 | D13: 1522.44 | E13: 1522.44 | F13: 1522.44 | G13: 1522.44 | H13: 1522.44 | I13: 1522.44 | J13: 1522.44 | K13: 1522.44 | L13: 1522.44 | O13: 0.99 | P13: 5974.2965 | Q13: 5965.9708 | R13: 6210.1211 | S13: 5934.8157
A14: conservative | B14: 1522.44 | C14: 1522.44 | D14: 1522.44 | E14: 1522.44 | F14: 1522.44 | G14: 1522.44 | H14: 1522.44 | I14: 1522.44 | J14: 1522.44 | K14: 1522.44 | L14: 1522.44
A15: Sum of E_storage_charge_MWh
A16: envelope | B16: 6325.1542 | C16: 6428.2441 | D16: 6242.0619 | E16: 6286.558 | F16: 6278.5345 | G16: 6277.2416 | H16: 6278.8007 | I16: 6303.3097 | J16: 6631.6181 | K16: 6471.6447 | L16: 6456.3168 | M16: =GETPIVOTDATA("Sum of E_storage_charge_MWh",$A$3,"model_type","envelope","rho",0)-GETPIVOTDATA("Sum of E_storage_discharge_MWh",$A$3,"model_type","envelope","rho",0) -> 892.14959 | N16: =GETPIVOTDATA("Sum of E_storage_charge_MWh",$A$3,"model_type",A16,"rho",C$4)-GETPIVOTDATA("Sum of E_storage_discharge_MWh",$A$3,"model_type",A16,"rho",C$4) -> 861.40101
A17: e-reserve | B17: 6317.0501 | C17: 6346.2681 | D17: 6243.3652 | E17: 6259.9571 | F17: 6288.9045 | G17: 6233.4728 | H17: 6330.4217 | I17: 6230.4672 | J17: 6349.474 | K17: 6345.9562 | L17: 6447.8256 | M17: =GETPIVOTDATA("Sum of E_storage_charge_MWh",$A$3,"model_type",A17,"rho",B$4)-GETPIVOTDATA("Sum of E_storage_discharge_MWh",$A$3,"model_type",A17,"rho",B$4) -> 892.14822 | N17: =GETPIVOTDATA("Sum of E_storage_charge_MWh",$A$3,"model_type",A17,"rho",C$4)-GETPIVOTDATA("Sum of E_storage_discharge_MWh",$A$3,"model_type",A17,"rho",C$4) -> 867.65824
A18: stochastic | B18: 6264.924 | C18: 6270.5021 | D18: 6097.4759 | E18: 6255.6857 | F18: 6223.4054 | G18: 6180.6081 | H18: 6135.0431 | I18: 5998.8817 | J18: 6552.6811 | K18: 6496.4041 | L18: 6577.8994 | M18: =GETPIVOTDATA("Sum of E_storage_charge_MWh",$A$3,"model_type",A18,"rho",B$4)-GETPIVOTDATA("Sum of E_storage_discharge_MWh",$A$3,"model_type",A18,"rho",B$4) -> 753.8915 | N18: =GETPIVOTDATA("Sum of E_storage_charge_MWh",$A$3,"model_type",A18,"rho",C$4)-GETPIVOTDATA("Sum of E_storage_discharge_MWh",$A$3,"model_type",A18,"rho",C$4) -> 708.013 | O18: =GETPIVOTDATA("Sum of E_storage_charge_MWh",$A$3,"model_type","stochastic","rho",D4)-GETPIVOTDATA("Sum of E_storage_discharge_MWh",$A$3,"model_type","stochastic","rho",D4) -> 700.56933
A19: conservative | B19: 6002.6455 | C19: 5967.1442 | D19: 5718.1959 | E19: 5707.7908 | F19: 5973.151 | G19: 6126.0154 | H19: 6039.0589 | I19: 5836.0789 | J19: 6134.8735 | K19: 6422.7963 | L19: 6416.212 | M19: =GETPIVOTDATA("Sum of E_storage_charge_MWh",$A$3,"model_type",A19,"rho",B$4)-GETPIVOTDATA("Sum of E_storage_discharge_MWh",$A$3,"model_type",A19,"rho",B$4) -> 840.19305 | N19: =GETPIVOTDATA("Sum of E_storage_charge_MWh",$A$3,"model_type",A19,"rho",C$4)-GETPIVOTDATA("Sum of E_storage_discharge_MWh",$A$3,"model_type",A19,"rho",C$4) -> 799.05686
A20: Sum of E_storage_discharge_MWh
A21: envelope | B21: 5433.0046 | C21: 5566.8431 | D21: 5396.3722 | E21: 5411.7532 | F21: 5379.5991 | G21: 5569.878 | H21: 5439.2158 | I21: 5567.3516 | J21: 5511.1867 | K21: 5600.5354 | L21: 5974.2965
A22: e-reserve | B22: 5424.9019 | C22: 5478.6098 | D22: 5398.313 | E22: 5387.174 | F22: 5389.9691 | G22: 5526.1092 | H22: 5476.2186 | I22: 5494.5092 | J22: 5243.6607 | K22: 5474.8469 | L22: 5965.9708
A23: stochastic | B23: 5511.0325 | C23: 5562.4891 | D23: 5396.9066 | E23: 5510.3994 | F23: 5468.8034 | G23: 5636.9777 | H23: 5453.6801 | I23: 5470.492 | J23: 5597.3612 | K23: 5773.6435 | L23: 6210.1211
A24: conservative | B24: 5162.4524 | C24: 5168.0874 | D24: 4905.3241 | E24: 4930.4861 | F24: 5124.4668 | G24: 5199.1736 | H24: 5117.2818 | I24: 5164.6962 | J24: 5075.3201 | K24: 5329.3554 | L24: 5934.8157
A25: Sum of input_load_MWh
A26: envelope | B26: 51861.382 | C26: 51911.958 | D26: 51913.841 | E26: 51887.665 | F26: 51874.651 | G26: 52073.625 | H26: 51918.196 | I26: 52029.717 | J26: 51655.648 | K26: 51897.803 | L26: 52354.743
A27: e-reserve | B27: 51861.382 | C27: 51911.958 | D27: 51913.841 | E27: 51887.665 | F27: 51874.651 | G27: 52073.625 | H27: 51918.196 | I27: 52029.717 | J27: 51655.648 | K27: 51897.803 | L27: 52354.743
A28: stochastic | B28: 51861.382 | C28: 51911.958 | D28: 51913.841 | E28: 51887.665 | F28: 51874.651 | G28: 52073.625 | H28: 51918.196 | I28: 52029.717 | J28: 51655.648 | K28: 51897.803 | L28: 52354.743 | O28: Sum of E_storage_charge_MWh | P28: Column Labels
A29: conservative | B29: 51861.382 | C29: 51911.958 | D29: 51913.841 | E29: 51887.665 | F29: 51874.651 | G29: 52073.625 | H29: 51918.196 | I29: 52029.717 | J29: 51655.648 | K29: 51897.803 | L29: 52354.743 | O29: Row Labels | P29: envelope | Q29: e-reserve | R29: stochastic | S29: conservative | T29: Grand Total
A30: Sum of input_RES_production_MWh | O30: 0.5 | P30: 6277.2416 | Q30: 6233.4728 | R30: 6180.6081 | S30: 6126.0154 | T30: 24817.338
A31: envelope | B31: 19374.064 | C31: 19374.064 | D31: 19374.064 | E31: 19374.064 | F31: 19374.064 | G31: 19374.064 | H31: 19374.064 | I31: 19374.064 | J31: 19374.064 | K31: 19374.064 | L31: 19374.064 | O31: 0.8 | P31: 6631.6181 | Q31: 6349.474 | R31: 6552.6811 | S31: 6134.8735 | T31: 25668.647
A32: e-reserve | B32: 19374.064 | C32: 19374.064 | D32: 19374.064 | E32: 19374.064 | F32: 19374.064 | G32: 19374.064 | H32: 19374.064 | I32: 19374.064 | J32: 19374.064 | K32: 19374.064 | L32: 19374.064 | O32: 0.99 | P32: 6456.3168 | Q32: 6447.8256 | R32: 6577.8994 | S32: 6416.212 | T32: 25898.254
A33: stochastic | B33: 19374.064 | C33: 19374.064 | D33: 19374.064 | E33: 19374.064 | F33: 19374.064 | G33: 19374.064 | H33: 19374.064 | I33: 19374.064 | J33: 19374.064 | K33: 19374.064 | L33: 19374.064 | O33: Grand Total | P33: 19365.176 | Q33: 19030.772 | R33: 19311.189 | S33: 18677.101 | T33: 76384.238
A34: conservative | B34: 19374.064 | C34: 19374.064 | D34: 19374.064 | E34: 19374.064 | F34: 19374.064 | G34: 19374.064 | H34: 19374.064 | I34: 19374.064 | J34: 19374.064 | K34: 19374.064 | L34: 19374.064
A35: Sum of EENS
A36: envelope | B36: 0 | C36: 0 | D36: 0.63745724 | E36: 2.021744 | F36: 0 | G36: 0 | H36: 0 | I36: 0 | J36: 0 | K36: 0 | L36: 0.62407091
A37: e-reserve | B37: 0 | C37: 0 | D37: 0 | E37: 0 | F37: 0 | G37: 0 | H37: 0 | I37: 0 | J37: 0 | K37: 0 | L37: 0
A38: stochastic | B38: 0 | C38: 0 | D38: 0 | E38: 0 | F38: 0 | G38: 0 | H38: 0 | I38: 0 | J38: 0 | K38: 0 | L38: 0
A39: conservative | B39: 0 | C39: 0 | D39: 0 | E39: 0 | F39: 0 | G39: 0 | H39: 0 | I39: 0 | J39: 0 | K39: 0 | L39: 0
A40: Sum of ELGEN
A41: envelope | B41: 0 | C41: 0 | D41: 0 | E41: 0 | F41: 0 | G41: 0 | H41: 0 | I41: 0 | J41: 0 | K41: 0 | L41: 0
A42: e-reserve | B42: 0 | C42: 0 | D42: -2.8990144e-14 | E42: 0 | F42: 0 | G42: 0 | H42: 0 | I42: 0 | J42: 0 | K42: 0 | L42: 0
...

Sheet gcd_KPI_adequacy
A1: model_type | B1: VLGEN | C1: rho | D1: solution_id | E1: configuration | F1: day | G1: OV_uc | H1: E_fixed_cost | I1: E_storage_discharge_MWh | J1: E_reserve_cost | K1: reserve_cost_uc | L1: E_storage_charge_MWh | M1: E_avg_marginal_energy_price_MU_MWh | N1: input_RES_production_MWh | O1: EENS_cost | P1: EOV | Q1: E_thermal_production_MWh | R1: avg_marginal_reserve_up_price_uc_MU_MWh | S1: E_production_cost | T1: avg_marginal_energy_price_uc_MU_MWh | U1: avg_marginal_reserve_down_price_uc_MU_MWh | V1: ECUR | W1: E_redispatch_cost | X1: LOLE | Y1: ELGEN_cost | Z1: E_start_cost | AA1: E_nonRES_nonThermal_production_MWh | AB1: CURE | AC1: ELGEN | AD1: EENS | AE1: EOPEX | AF1: input_load_MWh | AG1: OPEX_uc | AH1: mu | AI1: avg_marginal_energy_reserve_down_price_uc_MU_MWh | AJ1: avg_marginal_energy_reserve_up_price_uc_MU_MWh
A2: envelope | B2: 30 | C2: 0 | D2: solutions_v57.0.0.4s | E2: base_ramp_storage_envelopes_up_0_3_dn_0_3 | F2: 7 | G2: 800627.14 | H2: 51215.538 | I2: 5433.0046 | J2: 0.0099048019 | K2: 0.0099048019 | L2: 6325.1542 | M2: -0.1875 | N2: 19374.064 | O2: 0 | P2: 800627.14 | Q2: 31857.027 | R2: 0 | S2: 749411.59 | T2: 28.885101 | U2: 0.61362047 | V2: 2.8851921e-14 | W2: 2.7874346e-05 | X2: 0 | Y2: 0 | Z2: 0 | AA2: 1522.44 | AB2: 0 | AC2: 0 | AD2: 0 | AE2: 800627.13 | AF2: 51861.382 | AG2: 800627.13 | AH2: 0.3
A3: conservative | B3: 30 | C3: 0 | D3: solutions_v57.0.0.4s | E3: base_ramp_storage_envelopes_up_1_dn_1 | F3: 7 | G3: 808058.22 | H3: 57486.304 | I3: 5162.4524 | J3: 0.0099048019 | K3: 0.0099048019 | L3: 6002.6455 | M3: -0.037499983 | N3: 19374.064 | O3: 0 | P3: 808058.22 | Q3: 31805.071 | R3: 1.1209353 | S3: 750571.9 | T3: 29.265796 | U3: 4.1950847 | V3: 2.8851921e-14 | W3: 2.1961627e-05 | X3: 0 | Y3: 0 | Z3: 0 | AA3: 1522.44 | AB3: 0 | AC3: 0 | AD3: 0 | AE3: 808058.21 | AF3: 51861.382 | AG3: 808058.21 | AH3: 1
A4: envelope | B4: 30 | C4: 0.1 | D4: solutions_v57.0.1.4s | E4: base_ramp_storage_envelopes_up_0_3_dn_0_3 | F4: 7 | G4: 800160.26 | H4: 51215.538 | I4: 5566.8431 | J4: 0.0096977838 | K4: 0.0096977838 | L4: 6428.2441 | M4: 12.3125 | N4: 19374.064 | O4: 0 | P4: 800160.26 | Q4: 31876.855 | R4: 0 | S4: 748944.71 | T4: 28.744526 | U4: 0.53142576 | V4: 2.8851921e-14 | W4: 3.350448e-05 | X4: 0 | Y4: 0 | Z4: 0 | AA4: 1522.44 | AB4: 0 | AC4: 0 | AD4: 0 | AE4: 800160.25 | AF4: 51911.958 | AG4: 800160.25 | AH4: 0.3
A5: conservative | B5: 30 | C5: 0.1 | D5: solutions_v57.0.1.4s | E5: base_ramp_storage_envelopes_up_1_dn_1 | F5: 7 | G5: 807863.6 | H5: 57213.662 | I5: 5168.0874 | J5: 0.0096977838 | K5: 0.0096977838 | L5: 5967.1442 | M5: 1.7916667e-08 | N5: 19374.064 | O5: 0 | P5: 807863.6 | Q5: 31814.511 | R5: 1.2975446 | S5: 750649.92 | T5: 29.372078 | U5: 4.4382164 | V5: 2.8851921e-14 | W5: 8.4140059e-06 | X5: 0 | Y5: 0 | Z5: 0 | AA5: 1522.44 | AB5: 0 | AC5: 0 | AD5: 0 | AE5: 807863.59 | AF5: 51911.958 | AG5: 807863.59 | AH5: 1
A6: envelope | B6: 30 | C6: 0.2 | D6: solutions_v57.0.2.4s | E6: base_ramp_storage_envelopes_up_0_32_dn_0_32 | F6: 7 | G6: 800452.99 | H6: 51215.538 | I6: 5396.3722 | J6: 0.010291566 | K6: 0.010291566 | L6: 6242.0619 | M6: 92.719045 | N6: 19374.064 | O6: 6374.5724 | P6: 806827.57 | Q6: 31862.389 | R6: 0 | S6: 749237.45 | T6: 28.744526 | U6: 0.54119946 | V6: 2.8851921e-14 | W6: 1.0180402e-05 | X6: 0.01 | Y6: 0 | Z6: 0 | AA6: 1522.44 | AB6: 0 | AC6: 0 | AD6: 0.63745724 | AE6: 800452.98 | AF6: 51913.841 | AG6: 800452.98 | AH6: 0.32
